This error arise if I try to calculate fiscalcode_enc through an "inverse" function

2016-12-29 10:36:28,021 15209 ERROR daniela openerp.http: Exception during JSON request handling.
Traceback (most recent call last):
  File "/usr/lib/python2.7/dist-packages/openerp/http.py", line 536, in _handle_exception
    return super(JsonRequest, self)._handle_exception(exception)
  File "/usr/lib/python2.7/dist-packages/openerp/http.py", line 573, in dispatch
    result = self._call_function(**self.params)
  File "/usr/lib/python2.7/dist-packages/openerp/http.py", line 309, in _call_function
    return checked_call(self.db, *args, **kwargs)
  File "/usr/lib/python2.7/dist-packages/openerp/service/model.py", line 113, in wrapper
    return f(dbname, *args, **kwargs)
  File "/usr/lib/python2.7/dist-packages/openerp/http.py", line 306, in checked_call
    return self.endpoint(*a, **kw)
  File "/usr/lib/python2.7/dist-packages/openerp/http.py", line 802, in __call__
    return self.method(*args, **kw)
  File "/usr/lib/python2.7/dist-packages/openerp/http.py", line 402, in response_wrap
    response = f(*args, **kw)
  File "/usr/lib/python2.7/dist-packages/openerp/addons/web/controllers/main.py", line 937, in call_kw
    return self._call_kw(model, method, args, kwargs)
  File "/usr/lib/python2.7/dist-packages/openerp/addons/web/controllers/main.py", line 929, in _call_kw
    return getattr(request.registry.get(model), method)(request.cr, request.uid, *args, **kwargs)
  File "/usr/lib/python2.7/dist-packages/openerp/api.py", line 241, in wrapper
    return old_api(self, *args, **kwargs)
  File "/usr/lib/python2.7/dist-packages/openerp/api.py", line 363, in old_api
    result = method(recs, *args, **kwargs)
  File "/usr/lib/python2.7/dist-packages/openerp/addons/base/res/res_partner.py", line 564, in write
    result = super(res_partner, self).write(vals)
  File "/usr/lib/python2.7/dist-packages/openerp/api.py", line 239, in wrapper
    return new_api(self, *args, **kwargs)
  File "/usr/lib/python2.7/dist-packages/openerp/api.py", line 546, in new_api
    result = method(self._model, cr, uid, self.ids, *args, **kwargs)
  File "/usr/lib/python2.7/dist-packages/openerp/addons/mail/mail_thread.py", line 431, in write
    result = super(mail_thread, self).write(cr, uid, ids, values, context=context)
  File "/usr/lib/python2.7/dist-packages/openerp/api.py", line 241, in wrapper
    return old_api(self, *args, **kwargs)
  File "/usr/lib/python2.7/dist-packages/openerp/api.py", line 363, in old_api
    result = method(recs, *args, **kwargs)
  File "/usr/lib/python2.7/dist-packages/openerp/models.py", line 3781, in write
    self._fields[key].determine_inverse(self)
  File "/usr/lib/python2.7/dist-packages/openerp/fields.py", line 935, in determine_inverse
    self.inverse(records)
  File "/usr/lib/python2.7/dist-packages/openerp/custom/l10n_it_export_ts/models/partner.py", line 58, in _encrypt_fiscalcode_inverse
    record.fiscalcode_enc = util.encrypt(record.fiscalcode)
  File "/usr/lib/python2.7/dist-packages/openerp/custom/l10n_it_export_ts/util.py", line 111, in encrypt
    return base64.encodestring(cipher.encrypt(message))
  File "/usr/lib/python2.7/dist-packages/Crypto/Cipher/PKCS1_v1_5.py", line 137, in encrypt
    em = b('\x00\x02') + ps + bchr(0x00) + message
UnicodeDecodeError: 'ascii' codec can't decode byte 0xd6 in position 2: ordinal not in range(128)
2016-12-29 10:36:28,022 15209 ERROR daniela openerp.http: Exception during JSON request handling.
Traceback (most recent call last):
  File "/usr/lib/python2.7/dist-packages/openerp/http.py", line 536, in _handle_exception
    return super(JsonRequest, self)._handle_exception(exception)
  File "/usr/lib/python2.7/dist-packages/openerp/addons/base/ir/ir_http.py", line 173, in _dispatch
    result = request.dispatch()
  File "/usr/lib/python2.7/dist-packages/openerp/http.py", line 589, in dispatch
    return self._handle_exception(e)
  File "/usr/lib/python2.7/dist-packages/openerp/http.py", line 551, in _handle_exception
    return self._json_response(error=error)
  File "/usr/lib/python2.7/dist-packages/openerp/http.py", line 525, in _json_response
    body = simplejson.dumps(response)
  File "/usr/lib/python2.7/dist-packages/simplejson/__init__.py", line 354, in dumps
    return _default_encoder.encode(obj)
  File "/usr/lib/python2.7/dist-packages/simplejson/encoder.py", line 262, in encode
    chunks = self.iterencode(o, _one_shot=True)
  File "/usr/lib/python2.7/dist-packages/simplejson/encoder.py", line 340, in iterencode
    return _iterencode(o, 0)
UnicodeDecodeError: 'utf8' codec can't decode byte 0xd6 in position 2: invalid continuation byte
2016-12-29 10:36:28,025 15209 INFO daniela werkzeug: 127.0.0.1 - - [29/Dec/2016 10:36:28] "POST /web/dataset/call_kw/res.partner/write HTTP/1.1" 500 -
2016-12-29 10:36:28,036 15209 ERROR daniela werkzeug: Error on request:
Traceback (most recent call last):
  File "/usr/lib/python2.7/dist-packages/werkzeug/serving.py", line 177, in run_wsgi
    execute(self.server.app)
  File "/usr/lib/python2.7/dist-packages/werkzeug/serving.py", line 165, in execute
    application_iter = app(environ, start_response)
  File "/usr/lib/python2.7/dist-packages/openerp/service/server.py", line 285, in app
    return self.app(e, s)
  File "/usr/lib/python2.7/dist-packages/openerp/service/wsgi_server.py", line 216, in application
    return application_unproxied(environ, start_response)
  File "/usr/lib/python2.7/dist-packages/openerp/service/wsgi_server.py", line 202, in application_unproxied
    result = handler(environ, start_response)
  File "/usr/lib/python2.7/dist-packages/openerp/http.py", line 1289, in __call__
    return self.dispatch(environ, start_response)
  File "/usr/lib/python2.7/dist-packages/openerp/http.py", line 1263, in __call__
    return self.app(environ, start_wrapped)
  File "/usr/lib/python2.7/dist-packages/werkzeug/wsgi.py", line 579, in __call__
    return self.app(environ, start_response)
  File "/usr/lib/python2.7/dist-packages/openerp/http.py", line 1263, in __call__
    return self.app(environ, start_wrapped)
  File "/usr/lib/python2.7/dist-packages/werkzeug/wsgi.py", line 579, in __call__
    return self.app(environ, start_response)
  File "/usr/lib/python2.7/dist-packages/openerp/http.py", line 1434, in dispatch
    result = ir_http._dispatch()
  File "/usr/lib/python2.7/dist-packages/openerp/addons/website/models/ir_http.py", line 148, in _dispatch
    resp = super(ir_http, self)._dispatch()
  File "/usr/lib/python2.7/dist-packages/openerp/addons/base/ir/ir_http.py", line 177, in _dispatch
    return self._handle_exception(e)
  File "/usr/lib/python2.7/dist-packages/openerp/addons/website/models/ir_http.py", line 196, in _handle_exception
    return super(ir_http, self)._handle_exception(exception)
  File "/usr/lib/python2.7/dist-packages/openerp/addons/base/ir/ir_http.py", line 147, in _handle_exception
    return request._handle_exception(exception)
  File "/usr/lib/python2.7/dist-packages/openerp/http.py", line 551, in _handle_exception
    return self._json_response(error=error)
  File "/usr/lib/python2.7/dist-packages/openerp/http.py", line 525, in _json_response
    body = simplejson.dumps(response)
  File "/usr/lib/python2.7/dist-packages/simplejson/__init__.py", line 354, in dumps
    return _default_encoder.encode(obj)
  File "/usr/lib/python2.7/dist-packages/simplejson/encoder.py", line 262, in encode
    chunks = self.iterencode(o, _one_shot=True)
  File "/usr/lib/python2.7/dist-packages/simplejson/encoder.py", line 340, in iterencode
    return _iterencode(o, 0)
UnicodeDecodeError: 'utf8' codec can't decode byte 0xd6 in position 2: invalid continuation byte

